Workbook

Sheet Post Engagement Lift
A1: Post ID | B1: Platform | C1: Date | D1: Content Type | E1: Post Text | F1: Likes | G1: Shares | H1: Comments | I1: Impressions | J1: Total_Engagement | K1: Reach | L1: Clicks | M1: Primary_Hashtags | N1: Primary_Hashtags | O1: Primary_Hashtags | P1: Campaign_Name | Q1: Total_Budget | R1: Total_Budget | S1: Total_Budget | T1: ROI | U1: Growth | V1: END_DATE | W1: Period | AE1: =IFERROR( INDEX(Engagement!$A$2:$A$100, MATCH(M6, Campaign!$B$2:$B$100, 0)), "" )
A2: P001 | B2: Twitter | C2: 45649 | D2: Reel | E2: Check out our latest reel on twitter! | F2: 1461 | G2: 184 | H2: 344 | I2: 21915 | J2: =F2+G2+H2+L2 -> 2004 | K2: 21675 | L2: 15 | M2: FutureOfDriving | N2: AnytimeIsTeslaTime | P2: CybertruckLaunch | Q2: =IFERROR( INDEX(Campaign!$C$2:$C$100, MATCH(M2, Campaign!$E$2:$E$100, 0)), 0 ) -> 0 | R2: =IFERROR( INDEX(Campaign!$C$2:$C$100, MATCH(N2, Campaign!$E$2:$E$100, 0)), 0 ) -> 200000 | S2: =IFERROR( INDEX(Campaign!$C$2:$C$100, MATCH(O2, Campaign!$E$2:$E$100, 0)), 0 ) -> 0 | T2: =IF((Q2+R2+S2)=0, "", J2/(Q2+R2+S2)) -> 0.01002 | U2: =(F2+H2+G2)/I2 -> 0.090759754 | V2: =IFERROR( INDEX(Campaign!$A$2:$A$100, MATCH(M6, Campaign!$E$2:$E$100, 0)), "" ) -> 45488 | W2: =IF(TRIM(O2)="","Before", "During") -> Before
A3: P002 | B3: Twitter | C3: 45750 | D3: Text | E3: Check out our latest text on twitter! | F3: 4054 | G3: 389 | H3: 493 | I3: 64864 | J3: =F3+G3+H3+L3 -> 5053 | K3: 64383 | L3: 117 | M3: TeslaCoInnovation | N3: BetterWithTesla | P3: ModelYCampaign | Q3: =IFERROR( INDEX(Campaign!$C$2:$C$100, MATCH(M3, Campaign!$E$2:$E$100, 0)), 0 ) -> 0 | R3: =IFERROR( INDEX(Campaign!$C$2:$C$100, MATCH(N3, Campaign!$E$2:$E$100, 0)), 0 ) -> 180000 | S3: =IFERROR( INDEX(Campaign!$C$2:$C$100, MATCH(O3, Campaign!$E$2:$E$100, 0)), 0 ) -> 0 | T3: =IF((Q3+R3+S3)=0, "", J3/(Q3+R3+S3)) -> 0.028072222 | U3: =(F3+H3+G3)/I3 -> 0.076097681 | V3: =IFERROR( INDEX(Campaign!$A$2:$A$100, MATCH(M7, Campaign!$E$2:$E$100, 0)), "" ) | W3: =IF(TRIM(O3)="","Before", "During") -> Before
A4: P003 | B4: YouTube | C4: 45789 | D4: Reel | E4: Check out our latest reel on youtube! | F4: 2795 | G4: 105 | H4: 49 | I4: 53105 | J4: =F4+G4+H4+L4 -> 3153 | K4: 52307 | L4: 204 | M4: TeslaCoInnovation | P4: FSDUpdate | Q4: =IFERROR( INDEX(Campaign!$C$2:$C$100, MATCH(M4, Campaign!$E$2:$E$100, 0)), 0 ) -> 0 | R4: =IFERROR( INDEX(Campaign!$C$2:$C$100, MATCH(N4, Campaign!$E$2:$E$100, 0)), 0 ) -> 0 | S4: =IFERROR( INDEX(Campaign!$C$2:$C$100, MATCH(O4, Campaign!$E$2:$E$100, 0)), 0 ) -> 0 | T4: =IF((Q4+R4+S4)=0, "", J4/(Q4+R4+S4)) | U4: =(F4+H4+G4)/I4 -> 0.055531494 | V4: =IFERROR( INDEX(Campaign!$A$2:$A$100, MATCH(M8, Campaign!$E$2:$E$100, 0)), "" ) | W4: =IF(TRIM(O4)="","Before", "During") -> Before
A5: P004 | B5: Instagram | C5: 45516 | D5: Story | E5: Check out our latest story on instagram! | F5: 2404 | G5: 363 | H5: 138 | I5: 19232 | J5: =F5+G5+H5+L5 -> 3033 | K5: 18636 | L5: 128 | M5: EVRevolution | P5: SustainabilityDrive | Q5: =IFERROR( INDEX(Campaign!$C$2:$C$100, MATCH(M5, Campaign!$E$2:$E$100, 0)), 0 ) -> 150000 | R5: =IFERROR( INDEX(Campaign!$C$2:$C$100, MATCH(N5, Campaign!$E$2:$E$100, 0)), 0 ) -> 0 | S5: =IFERROR( INDEX(Campaign!$C$2:$C$100, MATCH(O5, Campaign!$E$2:$E$100, 0)), 0 ) -> 0 | T5: =IF((Q5+R5+S5)=0, "", J5/(Q5+R5+S5)) -> 0.02022 | U5: =(F5+H5+G5)/I5 -> 0.15105033 | V5: =IFERROR( INDEX(Campaign!$A$2:$A$100, MATCH(M9, Campaign!$E$2:$E$100, 0)), "" ) -> 45488 | W5: =IF(TRIM(O5)="","Before", "During") -> Before
A6: P005 | B6: YouTube | C6: 45469 | D6: Reel | E6: Check out our latest reel on youtube! | F6: 3557 | G6: 687 | H6: 424 | I6: 71140 | J6: =F6+G6+H6+L6 -> 4892 | K6: 70701 | L6: 224 | M6: EVRevolution | N6: TeslaCoInnovation | P6: CybertruckLaunch | Q6: =IFERROR( INDEX(Campaign!$C$2:$C$100, MATCH(M6, Campaign!$E$2:$E$100, 0)), 0 ) -> 150000 | R6: =IFERROR( INDEX(Campaign!$C$2:$C$100, MATCH(N6, Campaign!$E$2:$E$100, 0)), 0 ) -> 0 | S6: =IFERROR( INDEX(Campaign!$C$2:$C$100, MATCH(O6, Campaign!$E$2:$E$100, 0)), 0 ) -> 0 | T6: =IF((Q6+R6+S6)=0, "", J6/(Q6+R6+S6)) -> 0.032613333 | U6: =(F6+H6+G6)/I6 -> 0.065617093 | V6: =IFERROR( INDEX(Campaign!$A$2:$A$100, MATCH(M10, Campaign!$E$2:$E$100, 0)), "" ) | W6: =IF(TRIM(O6)="","Before", "During") -> Before
A7: P006 | B7: Facebook | C7: 45596 | D7: Carousel | E7: Check out our latest carousel on facebook! | F7: 2945 | G7: 930 | H7: 355 | I7: 23560 | J7: =F7+G7+H7+L7 -> 4486 | K7: 23275 | L7: 256 | M7: TeslaCoInnovation | P7: ModelYCampaign | Q7: =IFERROR( INDEX(Campaign!$C$2:$C$100, MATCH(M7, Campaign!$E$2:$E$100, 0)), 0 ) -> 0 | R7: =IFERROR( INDEX(Campaign!$C$2:$C$100, MATCH(N7, Campaign!$E$2:$E$100, 0)), 0 ) -> 0 | S7: =IFERROR( INDEX(Campaign!$C$2:$C$100, MATCH(O7, Campaign!$E$2:$E$100, 0)), 0 ) -> 0 | T7: =IF((Q7+R7+S7)=0, "", J7/(Q7+R7+S7)) | U7: =(F7+H7+G7)/I7 -> 0.1795416 | V7: =IFERROR( INDEX(Campaign!$A$2:$A$100, MATCH(M11, Campaign!$E$2:$E$100, 0)), "" ) | W7: =IF(TRIM(O7)="","Before", "During") -> Before
A8: P007 | B8: Twitter | C8: 45467 | D8: Carousel | E8: Check out our latest carousel on twitter! | F8: 3860 | G8: 201 | H8: 279 | I8: 61760 | J8: =F8+G8+H8+L8 -> 4575 | K8: 61660 | L8: 235 | M8: TeslaCoInnovation | P8: ModelYCampaign | Q8: =IFERROR( INDEX(Campaign!$C$2:$C$100, MATCH(M8, Campaign!$E$2:$E$100, 0)), 0 ) -> 0 | R8: =IFERROR( INDEX(Campaign!$C$2:$C$100, MATCH(N8, Campaign!$E$2:$E$100, 0)), 0 ) -> 0 | S8: =IFERROR( INDEX(Campaign!$C$2:$C$100, MATCH(O8, Campaign!$E$2:$E$100, 0)), 0 ) -> 0 | T8: =IF((Q8+R8+S8)=0, "", J8/(Q8+R8+S8)) | U8: =(F8+H8+G8)/I8 -> 0.070272021 | V8: =IFERROR( INDEX(Campaign!$A$2:$A$100, MATCH(M12, Campaign!$E$2:$E$100, 0)), "" ) | W8: =IF(TRIM(O8)="","Before", "During") -> Before
A9: P008 | B9: YouTube | C9: 45486 | D9: Image | E9: Check out our latest image on youtube! | F9: 3929 | G9: 262 | H9: 278 | I9: 43219 | J9: =F9+G9+H9+L9 -> 4508 | K9: 42841 | L9: 39 | M9: EVRevolution | P9: SustainabilityDrive | Q9: =IFERROR( INDEX(Campaign!$C$2:$C$100, MATCH(M9, Campaign!$E$2:$E$100, 0)), 0 ) -> 150000 | R9: =IFERROR( INDEX(Campaign!$C$2:$C$100, MATCH(N9, Campaign!$E$2:$E$100, 0)), 0 ) -> 0 | S9: =IFERROR( INDEX(Campaign!$C$2:$C$100, MATCH(O9, Campaign!$E$2:$E$100, 0)), 0 ) -> 0 | T9: =IF((Q9+R9+S9)=0, "", J9/(Q9+R9+S9)) -> 0.030053333 | U9: =(F9+H9+G9)/I9 -> 0.1034036 | V9: =IFERROR( INDEX(Campaign!$A$2:$A$100, MATCH(M13, Campaign!$E$2:$E$100, 0)), "" ) | W9: =IF(TRIM(O9)="","Before", "During") -> Before
A10: P009 | B10: Facebook | C10: 45534 | D10: Text | E10: Check out our latest text on facebook! | F10: 3784 | G10: 808 | H10: 404 | I10: 56760 | J10: =F10+G10+H10+L10 -> 5127 | K10: 56343 | L10: 131 | M10: TeslaCoInnovation | P10: ModelYCampaign | Q10: =IFERROR( INDEX(Campaign!$C$2:$C$100, MATCH(M10, Campaign!$E$2:$E$100, 0)), 0 ) -> 0 | R10: =IFERROR( INDEX(Campaign!$C$2:$C$100, MATCH(N10, Campaign!$E$2:$E$100, 0)), 0 ) -> 0 | S10: =IFERROR( INDEX(Campaign!$C$2:$C$100, MATCH(O10, Campaign!$E$2:$E$100, 0)), 0 ) -> 0 | T10: =IF((Q10+R10+S10)=0, "", J10/(Q10+R10+S10)) | U10: =(F10+H10+G10)/I10 -> 0.088019732 | V10: =IFERROR( INDEX(Campaign!$A$2:$A$100, MATCH(M14, Campaign!$E$2:$E$100, 0)), "" ) -> 45488 | W10: =IF(TRIM(O10)="","Before", "During") -> Before
A11: P010 | B11: Facebook | C11: 45727 | D11: Image | E11: Check out our latest image on facebook! | F11: 4241 | G11: 902 | H11: 47 | I11: 72097 | J11: =F11+G11+H11+L11 -> 5357 | K11: 71598 | L11: 167 | M11: TeslaCoInnovation | P11: ModelYCampaign | Q11: =IFERROR( INDEX(Campaign!$C$2:$C$100, MATCH(M11, Campaign!$E$2:$E$100, 0)), 0 ) -> 0 | R11: =IFERROR( INDEX(Campaign!$C$2:$C$100, MATCH(N11, Campaign!$E$2:$E$100, 0)), 0 ) -> 0 | S11: =IFERROR( INDEX(Campaign!$C$2:$C$100, MATCH(O11, Campaign!$E$2:$E$100, 0)), 0 ) -> 0 | T11: =IF((Q11+R11+S11)=0, "", J11/(Q11+R11+S11)) | U11: =(F11+H11+G11)/I11 -> 0.071986352 | V11: =IFERROR( INDEX(Campaign!$A$2:$A$100, MATCH(M15, Campaign!$E$2:$E$100, 0)), "" ) | W11: =IF(TRIM(O11)="","Before", "During") -> Before | Y11: Campaign Name | Z11: Avg Engagement Before | AA11: Avg Engagement During | AB11: Uplift
A12: P011 | B12: Instagram | C12: 45690 | D12: Story | E12: Check out our latest story on instagram! | F12: 1792 | G12: 614 | H12: 497 | I12: 25088 | J12: =F12+G12+H12+L12 -> 2968 | K12: 24675 | L12: 65 | M12: FutureOfDriving | P12: SustainabilityDrive | Q12: =IFERROR( INDEX(Campaign!$C$2:$C$100, MATCH(M12, Campaign!$E$2:$E$100, 0)), 0 ) -> 0 | R12: =IFERROR( INDEX(Campaign!$C$2:$C$100, MATCH(N12, Campaign!$E$2:$E$100, 0)), 0 ) -> 0 | S12: =IFERROR( INDEX(Campaign!$C$2:$C$100, MATCH(O12, Campaign!$E$2:$E$100, 0)), 0 ) -> 0 | T12: =IF((Q12+R12+S12)=0, "", J12/(Q12+R12+S12)) | U12: =(F12+H12+G12)/I12 -> 0.11571269 | V12: =IFERROR( INDEX(Campaign!$A$2:$A$100, MATCH(M16, Campaign!$E$2:$E$100, 0)), "" ) | W12: =IF(TRIM(O12)="","Before", "During") -> Before | Y12: CybertruckLaunch | Z12: =AVERAGEIFS($J:$J,$P:$P,Y12,$W:$W,"Before") -> 3721.0213 | AA12: =AVERAGEIFS($J:$J,$P:$P,Y12,$W:$W,"During") -> 5447 | AB12: =(AA12-Z12)/Z12*100 -> 46.384543
A13: P012 | B13: Facebook | C13: 45494 | D13: Reel | E13: Check out our latest reel on facebook! | F13: 1946 | G13: 686 | H13: 377 | I13: 23352 | J13: =F13+G13+H13+L13 -> 3222 | K13: 22982 | L13: 213 | M13: FutureOfDriving | P13: FSDUpdate | Q13: =IFERROR( INDEX(Campaign!$C$2:$C$100, MATCH(M13, Campaign!$E$2:$E$100, 0)), 0 ) -> 0 | R13: =IFERROR( INDEX(Campaign!$C$2:$C$100, MATCH(N13, Campaign!$E$2:$E$100, 0)), 0 ) -> 0 | S13: =IFERROR( INDEX(Campaign!$C$2:$C$100, MATCH(O13, Campaign!$E$2:$E$100, 0)), 0 ) -> 0 | T13: =IF((Q13+R13+S13)=0, "", J13/(Q13+R13+S13)) | U13: =(F13+H13+G13)/I13 -> 0.12885406 | V13: =IFERROR( INDEX(Campaign!$A$2:$A$100, MATCH(M17, Campaign!$E$2:$E$100, 0)), "" ) | W13: =IF(TRIM(O13)="","Before", "During") -> Before | Y13: ModelYCampaign | Z13: =AVERAGEIFS($J:$J,$P:$P,Y13,$W:$W,"Before") -> 3690.8364 | AA13: =AVERAGEIFS($J:$J,$P:$P,Y13,$W:$W,"During") -> 2871.6667 | AB13: =(AA13-Z13)/Z13*100 -> -22.19469
A14: P013 | B14: YouTube | C14: 45614 | D14: Carousel | E14: Check out our latest carousel on youtube! | F14: 1171 | G14: 286 | H14: 231 | I14: 22249 | J14: =F14+G14+H14+L14 -> 1802 | K14: 21282 | L14: 114 | M14: EVRevolution | P14: CybertruckLaunch | Q14: =IFERROR( INDEX(Campaign!$C$2:$C$100, MATCH(M14, Campaign!$E$2:$E$100, 0)), 0 ) -> 150000 | R14: =IFERROR( INDEX(Campaign!$C$2:$C$100, MATCH(N14, Campaign!$E$2:$E$100, 0)), 0 ) -> 0 | S14: =IFERROR( INDEX(Campaign!$C$2:$C$100, MATCH(O14, Campaign!$E$2:$E$100, 0)), 0 ) -> 0 | T14: =IF((Q14+R14+S14)=0, "", J14/(Q14+R14+S14)) -> 0.012013333 | U14: =(F14+H14+G14)/I14 -> 0.075868578 | V14: =IFERROR( INDEX(Campaign!$A$2:$A$100, MATCH(M18, Campaign!$E$2:$E$100, 0)), "" ) -> 45488 | W14: =IF(TRIM(O14)="","Before", "During") -> Before | Y14: FSDUpdate | Z14: =AVERAGEIFS($J:$J,$P:$P,Y14,$W:$W,"Before") -> 3689.9683 | AA14: =AVERAGEIFS($J:$J,$P:$P,Y14,$W:$W,"During") -> 2596.25 | AB14: =(AA14-Z14)/Z14*100 -> -29.640316
A15: P014 | B15: Facebook | C15: 45704 | D15: Story | E15: Check out our latest story on facebook! | F15: 4242 | G15: 555 | H15: 131 | I15: 33936 | J15: =F15+G15+H15+L15 -> 5193 | K15: 33802 | L15: 265 | M15: FutureOfDriving | Q15: =IFERROR( INDEX(Campaign!$C$2:$C$100, MATCH(M15, Campaign!$E$2:$E$100, 0)), 0 ) -> 0 | R15: =IFERROR( INDEX(Campaign!$C$2:$C$100, MATCH(N15, Campaign!$E$2:$E$100, 0)), 0 ) -> 0 | S15: =IFERROR( INDEX(Campaign!$C$2:$C$100, MATCH(O15, Campaign!$E$2:$E$100, 0)), 0 ) -> 0 | T15: =IF((Q15+R15+S15)=0, "", J15/(Q15+R15+S15)) | U15: =(F15+H15+G15)/I15 -> 0.14521452 | V15: =IFERROR( INDEX(Campaign!$A$2:$A$100, MATCH(M19, Campaign!$E$2:$E$100, 0)), "" ) | W15: =IF(TRIM(O15)="","Before", "During") -> Before | Y15: SustainabilityDrive | Z15: =AVERAGEIFS($J:$J,$P:$P,Y15,$W:$W,"Before") -> 3533.6522 | AA15: =AVERAGEIFS($J:$J,$P:$P,Y15,$W:$W,"During") -> 3675 | AB15: =(AA15-Z15)/Z15*100 -> 4.0000492
A16: P015 | B16: Facebook | C16: 45589 | D16: Video | E16: Check out our latest video on facebook! | F16: 3888 | G16: 604 | H16: 128 | I16: 77760 | J16: =F16+G16+H16+L16 -> 4640 | K16: 77167 | L16: 20 | M16: FutureOfDriving | P16: CybertruckLaunch | Q16: =IFERROR( INDEX(Campaign!$C$2:$C$100, MATCH(M16, Campaign!$E$2:$E$100, 0)), 0 ) -> 0 | R16: =IFERROR( INDEX(Campaign!$C$2:$C$100, MATCH(N16, Campaign!$E$2:$E$100, 0)), 0 ) -> 0 | S16: =IFERROR( INDEX(Campaign!$C$2:$C$100, MATCH(O16, Campaign!$E$2:$E$100, 0)), 0 ) -> 0 | T16: =IF((Q16+R16+S16)=0, "", J16/(Q16+R16+S16)) | U16: =(F16+H16+G16)/I16 -> 0.05941358 | V16: =IFERROR( INDEX(Campaign!$A$2:$A$100, MATCH(M20, Campaign!$E$2:$E$100, 0)), "" ) | W16: =IF(TRIM(O16)="","Before", "During") -> Before
A17: P016 | B17: Facebook | C17: 45530 | D17: Text | E17: Check out our latest text on facebook! | F17: 3452 | G17: 377 | H17: 360 | I17: 55232 | J17: =F17+G17+H17+L17 -> 4276 | K17: 55075 | L17: 87 | M17: FutureOfDriving | P17: FSDUpdate | Q17: =IFERROR( INDEX(Campaign!$C$2:$C$100, MATCH(M17, Campaign!$E$2:$E$100, 0)), 0 ) -> 0 | R17: =IFERROR( INDEX(Campaign!$C$2:$C$100, MATCH(N17, Campaign!$E$2:$E$100, 0)), 0 ) -> 0 | S17: =IFERROR( INDEX(Campaign!$C$2:$C$100, MATCH(O17, Campaign!$E$2:$E$100, 0)), 0 ) -> 0 | T17: =IF((Q17+R17+S17)=0, "", J17/(Q17+R17+S17)) | U17: =(F17+H17+G17)/I17 -> 0.075843714 | V17: =IFERROR( INDEX(Campaign!$A$2:$A$100, MATCH(M21, Campaign!$E$2:$E$100, 0)), "" ) | W17: =IF(TRIM(O17)="","Before", "During") -> Before
A18: P017 | B18: Facebook | C18: 45782 | D18: Text | E18: Check out our latest text on facebook! | F18: 4441 | G18: 511 | H18: 70 | I18: 53292 | J18: =F18+G18+H18+L18 -> 5181 | K18: 53082 | L18: 159 | M18: EVRevolution | P18: SustainabilityDrive | Q18: =IFERROR( INDEX(Campaign!$C$2:$C$100, MATCH(M18, Campaign!$E$2:$E$100, 0)), 0 ) -> 150000 | R18: =IFERROR( INDEX(Campaign!$C$2:$C$100, MATCH(N18, Campaign!$E$2:$E$100, 0)), 0 ) -> 0 | S18: =IFERROR( INDEX(Campaign!$C$2:$C$100, MATCH(O18, Campaign!$E$2:$E$100, 0)), 0 ) -> 0 | T18: =IF((Q18+R18+S18)=0, "", J18/(Q18+R18+S18)) -> 0.03454 | U18: =(F18+H18+G18)/I18 -> 0.094235533 | V18: =IFERROR( INDEX(Campaign!$A$2:$A$100, MATCH(M22, Campaign!$E$2:$E$100, 0)), "" ) | W18: =IF(TRIM(O18)="","Before", "During") -> Before
A19: P018 | B19: Instagram | C19: 45523 | D19: Reel | E19: Check out our latest reel on instagram! | F19: 3000 | G19: 382 | H19: 325 | I19: 36000 | J19: =F19+G19+H19+L19 -> 3726 | K19: 35819 | L19: 19 | M19: FutureOfDriving | P19: CybertruckLaunch | Q19: =IFERROR( INDEX(Campaign!$C$2:$C$100, MATCH(M19, Campaign!$E$2:$E$100, 0)), 0 ) -> 0 | R19: =IFERROR( INDEX(Campaign!$C$2:$C$100, MATCH(N19, Campaign!$E$2:$E$100, 0)), 0 ) -> 0 | S19: =IFERROR( INDEX(Campaign!$C$2:$C$100, MATCH(O19, Campaign!$E$2:$E$100, 0)), 0 ) -> 0 | T19: =IF((Q19+R19+S19)=0, "", J19/(Q19+R19+S19)) | U19: =(F19+H19+G19)/I19 -> 0.10297222 | V19: =IFERROR( INDEX(Campaign!$A$2:$A$100, MATCH(M23, Campaign!$E$2:$E$100, 0)), "" ) | W19: =IF(TRIM(O19)="","Before", "During") -> Before
A20: P019 | B20: Instagram | C20: 45466 | D20: Video | E20: Check out our latest video on instagram! | F20: 1071 | G20: 519 | H20: 22 | I20: 16065 | J20: =F20+G20+H20+L20 -> 1715 | K20: 15865 | L20: 103 | M20: TeslaCoInnovation | P20: SustainabilityDrive | Q20: =IFERROR( INDEX(Campaign!$C$2:$C$100, MATCH(M20, Campaign!$E$2:$E$100, 0)), 0 ) -> 0 | R20: =IFERROR( INDEX(Campaign!$C$2:$C$100, MATCH(N20, Campaign!$E$2:$E$100, 0)), 0 ) -> 0 | S20: =IFERROR( INDEX(Campaign!$C$2:$C$100, MATCH(O20, Campaign!$E$2:$E$100, 0)), 0 ) -> 0 | T20: =IF((Q20+R20+S20)=0, "", J20/(Q20+R20+S20)) | U20: =(F20+H20+G20)/I20 -> 0.10034236 | V20: =IFERROR( INDEX(Campaign!$A$2:$A$100, MATCH(M24, Campaign!$E$2:$E$100, 0)), "" ) | W20: =IF(TRIM(O20)="","Before", "During") -> Before
A21: P020 | B21: Instagram | C21: 45544 | D21: Carousel | E21: Check out our latest carousel on instagram! | F21: 4054 | G21: 488 | H21: 373 | I21: 77026 | J21: =F21+G21+H21+L21 -> 4940 | K21: 76881 | L21: 25 | M21: TeslaCoInnovation | P21: CybertruckLaunch | Q21: =IFERROR( INDEX(Campaign!$C$2:$C$100, MATCH(M21, Campaign!$E$2:$E$100, 0)), 0 ) -> 0 | R21: =IFERROR( INDEX(Campaign!$C$2:$C$100, MATCH(N21, Campaign!$E$2:$E$100, 0)), 0 ) -> 0 | S21: =IFERROR( INDEX(Campaign!$C$2:$C$100, MATCH(O21, Campaign!$E$2:$E$100, 0)), 0 ) -> 0 | T21: =IF((Q21+R21+S21)=0, "", J21/(Q21+R21+S21)) | U21: =(F21+H21+G21)/I21 -> 0.063809623 | V21: =IFERROR( INDEX(Campaign!$A$2:$A$100, MATCH(M25, Campaign!$E$2:$E$100, 0)), "" ) | W21: =IF(TRIM(O21)="","Before", "During") -> Before
A22: P021 | B22: Instagram | C22: 45661 | D22: Reel | E22: Check out our latest reel on instagram! | F22: 4838 | G22: 640 | H22: 128 | I22: 72570 | J22: =F22+G22+H22+L22 -> 5689 | K22: 72396 | L22: 83 | M22: FutureOfDriving | P22: SustainabilityDrive | Q22: =IFERROR( INDEX(Campaign!$C$2:$C$100, MATCH(M22, Campaign!$E$2:$E$100, 0)), 0 ) -> 0 | R22: =IFERROR( INDEX(Campaign!$C$2:$C$100, MATCH(N22, Campaign!$E$2:$E$100, 0)), 0 ) -> 0 | S22: =IFERROR( INDEX(Campaign!$C$2:$C$100, MATCH(O22, Campaign!$E$2:$E$100, 0)), 0 ) -> 0 | T22: =IF((Q22+R22+S22)=0, "", J22/(Q22+R22+S22)) | U22: =(F22+H22+G22)/I22 -> 0.077249552 | V22: =IFERROR( INDEX(Campaign!$A$2:$A$100, MATCH(M26, Campaign!$E$2:$E$100, 0)), "" ) -> 45488 | W22: =IF(TRIM(O22)="","Before", "During") -> Before
A23: P022 | B23: Facebook | C23: 45715 | D23: Text | E23: Check out our latest text on facebook! | F23: 1570 | G23: 187 | H23: 260 | I23: 25120 | J23: =F23+G23+H23+L23 -> 2150 | K23: 24613 | L23: 133 | M23: TeslaCoInnovation | P23: SustainabilityDrive | Q23: =IFERROR( INDEX(Campaign!$C$2:$C$100, MATCH(M23, Campaign!$E$2:$E$100, 0)), 0 ) -> 0 | R23: =IFERROR( INDEX(Campaign!$C$2:$C$100, MATCH(N23, Campaign!$E$2:$E$100, 0)), 0 ) -> 0 | S23: =IFERROR( INDEX(Campaign!$C$2:$C$100, MATCH(O23, Campaign!$E$2:$E$100, 0)), 0 ) -> 0 | T23: =IF((Q23+R23+S23)=0, "", J23/(Q23+R23+S23)) | U23: =(F23+H23+G23)/I23 -> 0.080294586 | V23: =IFERROR( INDEX(Campaign!$A$2:$A$100, MATCH(M27, Campaign!$E$2:$E$100, 0)), "" ) | W23: =IF(TRIM(O23)="","Before", "During") -> Before
A24: P023 | B24: Facebook | C24: 45602 | D24: Video | E24: Check out our latest video on facebook! | F24: 1606 | G24: 547 | H24: 316 | I24: 32120 | J24: =F24+G24+H24+L24 -> 2694 | K24: 31736 | L24: 225 | M24: TeslaCoInnovation | N24: AnytimeIsTeslaTime | P24: ModelYCampaign | Q24: =IFERROR( INDEX(Campaign!$C$2:$C$100, MATCH(M24, Campaign!$E$2:$E$100, 0)), 0 ) -> 0 | R24: =IFERROR( INDEX(Campaign!$C$2:$C$100, MATCH(N24, Campaign!$E$2:$E$100, 0)), 0 ) -> 200000 | S24: =IFERROR( INDEX(Campaign!$C$2:$C$100, MATCH(O24, Campaign!$E$2:$E$100, 0)), 0 ) -> 0 | T24: =IF((Q24+R24+S24)=0, "", J24/(Q24+R24+S24)) -> 0.01347 | U24: =(F24+H24+G24)/I24 -> 0.076867995 | V24: =IFERROR( INDEX(Campaign!$A$2:$A$100, MATCH(M28, Campaign!$E$2:$E$100, 0)), "" ) | W24: =IF(TRIM(O24)="","Before", "During") -> Before
A25: P024 | B25: Facebook | C25: 45680 | D25: Video | E25: Check out our latest video on facebook! | F25: 3961 | G25: 761 | H25: 131 | I25: 67337 | J25: =F25+G25+H25+L25 -> 5014 | K25: 66615 | L25: 161 | M25: FutureOfDriving | P25: FSDUpdate | Q25: =IFERROR( INDEX(Campaign!$C$2:$C$100, MATCH(M25, Campaign!$E$2:$E$100, 0)), 0 ) -> 0 | R25: =IFERROR( INDEX(Campaign!$C$2:$C$100, MATCH(N25, Campaign!$E$2:$E$100, 0)), 0 ) -> 0 | S25: =IFERROR( INDEX(Campaign!$C$2:$C$100, MATCH(O25, Campaign!$E$2:$E$100, 0)), 0 ) -> 0 | T25: =IF((Q25+R25+S25)=0, "", J25/(Q25+R25+S25)) | U25: =(F25+H25+G25)/I25 -> 0.072070333 | V25: =IFERROR( INDEX(Campaign!$A$2:$A$100, MATCH(M29, Campaign!$E$2:$E$100, 0)), "" ) | W25: =IF(TRIM(O25)="","Before", "During") -> Before
A26: P025 | B26: Twitter | C26: 45757 | D26: Carousel | E26: Check out our latest carousel on twitter! | F26: 3128 | G26: 211 | H26: 197 | I26: 59432 | J26: =F26+G26+H26+L26 -> 3774 | K26: 59182 | L26: 238 | M26: EVRevolution | Q26: =IFERROR( INDEX(Campaign!$C$2:$C$100, MATCH(M26, Campaign!$E$2:$E$100, 0)), 0 ) -> 150000 | R26: =IFERROR( INDEX(Campaign!$C$2:$C$100, MATCH(N26, Campaign!$E$2:$E$100, 0)), 0 ) -> 0 | S26: =IFERROR( INDEX(Campaign!$C$2:$C$100, MATCH(O26, Campaign!$E$2:$E$100, 0)), 0 ) -> 0 | T26: =IF((Q26+R26+S26)=0, "", J26/(Q26+R26+S26)) -> 0.02516 | U26: =(F26+H26+G26)/I26 -> 0.059496568 | V26: =IFERROR( INDEX(Campaign!$A$2:$A$100, MATCH(M30, Campaign!$E$2:$E$100, 0)), "" ) | W26: =IF(TRIM(O26)="","Before", "During") -> Before
A27: P026 | B27: YouTube | C27: 45752 | D27: Reel | E27: Check out our latest reel on youtube! | F27: 3009 | G27: 413 | H27: 358 | I27: 42126 | J27: =F27+G27+H27+L27 -> 3991 | K27: 41309 | L27: 211 | M27: FutureOfDriving | P27: ModelYCampaign | Q27: =IFERROR( INDEX(Campaign!$C$2:$C$100, MATCH(M27, Campaign!$E$2:$E$100, 0)), 0 ) -> 0 | R27: =IFERROR( INDEX(Campaign!$C$2:$C$100, MATCH(N27, Campaign!$E$2:$E$100, 0)), 0 ) -> 0 | S27: =IFERROR( INDEX(Campaign!$C$2:$C$100, MATCH(O27, Campaign!$E$2:$E$100, 0)), 0 ) -> 0 | T27: =IF((Q27+R27+S27)=0, "", J27/(Q27+R27+S27)) | U27: =(F27+H27+G27)/I27 -> 0.089730808 | V27: =IFERROR( INDEX(Campaign!$A$2:$A$100, MATCH(M31, Campaign!$E$2:$E$100, 0)), "" ) -> 45488 | W27: =IF(TRIM(O27)="","Before", "During") -> Before
A28: P027 | B28: YouTube | C28: 45552 | D28: Text | E28: Check out our latest text on youtube! | F28: 2076 | G28: 195 | H28: 104 | I28: 33216 | J28: =F28+G28+H28+L28 -> 2426 | K28: 32244 | L28: 51 | M28: FutureOfDriving | P28: SustainabilityDrive | Q28: =IFERROR( INDEX(Campaign!$C$2:$C$100, MATCH(M28, Campaign!$E$2:$E$100, 0)), 0 ) -> 0 | R28: =IFERROR( INDEX(Campaign!$C$2:$C$100, MATCH(N28, Campaign!$E$2:$E$100, 0)), 0 ) -> 0 | S28: =IFERROR( INDEX(Campaign!$C$2:$C$100, MATCH(O28, Campaign!$E$2:$E$100, 0)), 0 ) -> 0 | T28: =IF((Q28+R28+S28)=0, "", J28/(Q28+R28+S28)) | U28: =(F28+H28+G28)/I28 -> 0.071501686 | V28: =IFERROR( INDEX(Campaign!$A$2:$A$100, MATCH(M32, Campaign!$E$2:$E$100, 0)), "" ) | W28: =IF(TRIM(O28)="","Before", "During") -> Before
A29: P028 | B29: Instagram | C29: 45720 | D29: Video | E29: Check out our latest video on instagram! | F29: 432 | G29: 624 | H29: 123 | I29: 6912 | J29: =F29+G29+H29+L29 -> 1258 | K29: 6259 | L29: 79 | M29: FutureOfDriving | P29: SustainabilityDrive | Q29: =IFERROR( INDEX(Campaign!$C$2:$C$100, MATCH(M29, Campaign!$E$2:$E$100, 0)), 0 ) -> 0 | R29: =IFERROR( INDEX(Campaign!$C$2:$C$100, MATCH(N29, Campaign!$E$2:$E$100, 0)), 0 ) -> 0 | S29: =IFERROR( INDEX(Campaign!$C$2:$C$100, MATCH(O29, Campaign!$E$2:$E$100, 0)), 0 ) -> 0 | T29: =IF((Q29+R29+S29)=0, "", J29/(Q29+R29+S29)) | U29: =(F29+H29+G29)/I29 -> 0.17057292 | V29: =IFERROR( INDEX(Campaign!$A$2:$A$100, MATCH(M33, Campaign!$E$2:$E$100, 0)), "" ) -> 45488 | W29: =IF(TRIM(O29)="","Before", "During") -> Before
A30: P029 | B30: Instagram | C30: 45688 | D30: Carousel | E30: Check out our latest carousel on instagram! | F30: 2566 | G30: 118 | H30: 37 | I30: 12830 | J30: =F30+G30+H30+L30 -> 2942 | K30: 12264 | L30: 221 | M30: FutureOfDriving | P30: FSDUpdate | Q30: =IFERROR( INDEX(Campaign!$C$2:$C$100, MATCH(M30, Campaign!$E$2:$E$100, 0)), 0 ) -> 0 | R30: =IFERROR( INDEX(Campaign!$C$2:$C$100, MATCH(N30, Campaign!$E$2:$E$100, 0)), 0 ) -> 0 | S30: =IFERROR( INDEX(Campaign!$C$2:$C$100, MATCH(O30, Campaign!$E$2:$E$100, 0)), 0 ) -> 0 | T30: =IF((Q30+R30+S30)=0, "", J30/(Q30+R30+S30)) | U30: =(F30+H30+G30)/I30 -> 0.21208106 | V30: =IFERROR( INDEX(Campaign!$A$2:$A$100, MATCH(M34, Campaign!$E$2:$E$100, 0)), "" ) | W30: =IF(TRIM(O30)="","Before", "During") -> Before
A31: P030 | B31: Instagram | C31: 45713 | D31: Video | E31: Check out our latest video on instagram! | F31: 3095 | G31: 39 | H31: 78 | I31: 55710 | J31: =F31+G31+H31+L31 -> 3305 | K31: 54808 | L31: 93 | M31: EVRevolution | Q31: =IFERROR( INDEX(Campaign!$C$2:$C$100, MATCH(M31, Campaign!$E$2:$E$100, 0)), 0 ) -> 150000 | R31: =IFERROR( INDEX(Campaign!$C$2:$C$100, MATCH(N31, Campaign!$E$2:$E$100, 0)), 0 ) -> 0 | S31: =IFERROR( INDEX(Campaign!$C$2:$C$100, MATCH(O31, Campaign!$E$2:$E$100, 0)), 0 ) -> 0 | T31: =IF((Q31+R31+S31)=0, "", J31/(Q31+R31+S31)) -> 0.022033333 | U31: =(F31+H31+G31)/I31 -> 0.057655717 | V31: =IFERROR( INDEX(Campaign!$A$2:$A$100, MATCH(M35, Campaign!$E$2:$E$100, 0)), "" ) | W31: =IF(TRIM(O31)="","Before", "During") -> Before
A32: P031 | B32: Instagram | C32: 45642 | D32: Text | E32: Check out our latest text on instagram! | F32: 438 | G32: 153 | H32: 275 | I32: 3066 | J32: =F32+G32+H32+L32 -> 1148 | K32: 2701 | L32: 282 | M32: TeslaCoInnovation | P32: ModelYCampaign | Q32: =IFERROR( INDEX(Campaign!$C$2:$C$100, MATCH(M32, Campaign!$E$2:$E$100, 0)), 0 ) -> 0 | R32: =IFERROR( INDEX(Campaign!$C$2:$C$100, MATCH(N32, Campaign!$E$2:$E$100, 0)), 0 ) -> 0 | S32: =IFERROR( INDEX(Campaign!$C$2:$C$100, MATCH(O32, Campaign!$E$2:$E$100, 0)), 0 ) -> 0 | T32: =IF((Q32+R32+S32)=0, "", J32/(Q32+R32+S32)) | U32: =(F32+H32+G32)/I32 -> 0.28245271 | V32: =IFERROR( INDEX(Campaign!$A$2:$A$100, MATCH(M36, Campaign!$E$2:$E$100, 0)), "" ) | W32: =IF(TRIM(O32)="","Before", "During") -> Before
A33: P032 | B33: Twitter | C33: 45504 | D33: Carousel | E33: Check out our latest carousel on twitter! | F33: 2278 | G33: 10 | H33: 321 | I33: 13668 | J33: =F33+G33+H33+L33 -> 2884 | K33: 12676 | L33: 275 | M33: EVRevolution | P33: CybertruckLaunch | Q33: =IFERROR( INDEX(Campaign!$C$2:$C$100, MATCH(M33, Campaign!$E$2:$E$100, 0)), 0 ) -> 150000 | R33: =IFERROR( INDEX(Campaign!$C$2:$C$100, MATCH(N33, Campaign!$E$2:$E$100, 0)), 0 ) -> 0 | S33: =IFERROR( INDEX(Campaign!$C$2:$C$100, MATCH(O33, Campaign!$E$2:$E$100, 0)), 0 ) -> 0 | T33: =IF((Q33+R33+S33)=0, "", J33/(Q33+R33+S33)) -> 0.019226667 | U33: =(F33+H33+G33)/I33 -> 0.19088382 | V33: =IFERROR( INDEX(Campaign!$A$2:$A$100, MATCH(M37, Campaign!$E$2:$E$100, 0)), "" ) -> 45488 | W33: =IF(TRIM(O33)="","Before", "During") -> Before
A34: P033 | B34: Facebook | C34: 45525 | D34: Image | E34: Check out our latest image on facebook! | F34: 1407 | G34: 400 | H34: 351 | I34: 16884 | J34: =F34+G34+H34+L34 -> 2271 | K34: 15954 | L34: 113 | M34: TeslaCoInnovation | P34: CybertruckLaunch | Q34: =IFERROR( INDEX(Campaign!$C$2:$C$100, MATCH(M34, Campaign!$E$2:$E$100, 0)), 0 ) -> 0 | R34: =IFERROR( INDEX(Campaign!$C$2:$C$100, MATCH(N34, Campaign!$E$2:$E$100, 0)), 0 ) -> 0 | S34: =IFERROR( INDEX(Campaign!$C$2:$C$100, MATCH(O34, Campaign!$E$2:$E$100, 0)), 0 ) -> 0 | T34: =IF((Q34+R34+S34)=0, "", J34/(Q34+R34+S34)) | U34: =(F34+H34+G34)/I34 -> 0.12781331 | V34: =IFERROR( INDEX(Campaign!$A$2:$A$100, MATCH(M38, Campaign!$E$2:$E$100, 0)), "" ) -> 45488 | W34: =IF(TRIM(O34)="","Before", "During") -> Before
A35: P034 | B35: Facebook | C35: 45742 | D35: Text | E35: Check out our latest text on facebook! | F35: 1652 | G35: 89 | H35: 357 | I35: 29736 | J35: =F35+G35+H35+L35 -> 2313 | K35: 28771 | L35: 215 | M35: TeslaCoInnovation | P35: FSDUpdate | Q35: =IFERROR( INDEX(Campaign!$C$2:$C$100, MATCH(M35, Campaign!$E$2:$E$100, 0)), 0 ) -> 0 | R35: =IFERROR( INDEX(Campaign!$C$2:$C$100, MATCH(N35, Campaign!$E$2:$E$100, 0)), 0 ) -> 0 | S35: =IFERROR( INDEX(Campaign!$C$2:$C$100, MATCH(O35, Campaign!$E$2:$E$100, 0)), 0 ) -> 0 | T35: =IF((Q35+R35+S35)=0, "", J35/(Q35+R35+S35)) | U35: =(F35+H35+G35)/I35 -> 0.07055421 | V35: =IFERROR( INDEX(Campaign!$A$2:$A$100, MATCH(M39, Campaign!$E$2:$E$100, 0)), "" ) | W35: =IF(TRIM(O35)="","Before", "During") -> Before
A36: P035 | B36: Instagram | C36: 45626 | D36: Video | E36: Check out our latest video on instagram! | F36: 3775 | G36: 16 | H36: 239 | I36: 33975 | J36: =F36+G36+H36+L36 -> 4301 | K36: 33310 | L36: 271 | M36: FutureOfDriving | P36: ModelYCampaign | Q36: =IFERROR( INDEX(Campaign!$C$2:$C$100, MATCH(M36, Campaign!$E$2:$E$100, 0)), 0 ) -> 0 | R36: =IFERROR( INDEX(Campaign!$C$2:$C$100, MATCH(N36, Campaign!$E$2:$E$100, 0)), 0 ) -> 0 | S36: =IFERROR( INDEX(Campaign!$C$2:$C$100, MATCH(O36, Campaign!$E$2:$E$100, 0)), 0 ) -> 0 | T36: =IF((Q36+R36+S36)=0, "", J36/(Q36+R36+S36)) | U36: =(F36+H36+G36)/I36 -> 0.11861663 | V36: =IFERROR( INDEX(Campaign!$A$2:$A$100, MATCH(M40, Campaign!$E$2:$E$100, 0)), "" ) | W36: =IF(TRIM(O36)="","Before", "During") -> Before
A37: P036 | B37: Instagram | C37: 45766 | D37: Story | E37: Check out our latest story on instagram! | F37: 4518 | G37: 285 | H37: 383 | I37: 67770 | J37: =F37+G37+H37+L37 -> 5217 | K37: 67621 | L37: 31 | M37: EVRevolution | P37: ModelYCampaign | Q37: =IFERROR( INDEX(Campaign!$C$2:$C$100, MATCH(M37, Campaign!$E$2:$E$100, 0)), 0 ) -> 150000 | R37: =IFERROR( INDEX(Campaign!$C$2:$C$100, MATCH(N37, Campaign!$E$2:$E$100, 0)), 0 ) -> 0 | S37: =IFERROR( INDEX(Campaign!$C$2:$C$100, MATCH(O37, Campaign!$E$2:$E$100, 0)), 0 ) -> 0 | T37: =IF((Q37+R37+S37)=0, "", J37/(Q37+R37+S37)) -> 0.03478 | U37: =(F37+H37+G37)/I37 -> 0.076523535 | V37: =IFERROR( INDEX(Campaign!$A$2:$A$100, MATCH(M41, Campaign!$E$2:$E$100, 0)), "" ) -> 45488 | W37: =IF(TRIM(O37)="","Before", "During") -> Before
A38: P037 | B38: Facebook | C38: 45663 | D38: Carousel | E38: Check out our latest carousel on facebook! | F38: 3024 | G38: 925 | H38: 350 | I38: 24192 | J38: =F38+G38+H38+L38 -> 4335 | K38: 23518 | L38: 36 | M38: EVRevolution | P38: ModelYCampaign | Q38: =IFERROR( INDEX(Campaign!$C$2:$C$100, MATCH(M38, Campaign!$E$2:$E$100, 0)), 0 ) -> 150000 | R38: =IFERROR( INDEX(Campaign!$C$2:$C$100, MATCH(N38, Campaign!$E$2:$E$100, 0)), 0 ) -> 0 | S38: =IFERROR( INDEX(Campaign!$C$2:$C$100, MATCH(O38, Campaign!$E$2:$E$100, 0)), 0 ) -> 0 | T38: =IF((Q38+R38+S38)=0, "", J38/(Q38+R38+S38)) -> 0.0289 | U38: =(F38+H38+G38)/I38 -> 0.17770337 | V38: =IFERROR( INDEX(Campaign!$A$2:$A$100, MATCH(M42, Campaign!$E$2:$E$100, 0)), "" ) | W38: =IF(TRIM(O38)="","Before", "During") -> Before
A39: P038 | B39: YouTube | C39: 45705 | D39: Reel | E39: Check out our latest reel on youtube! | F39: 3138 | G39: 123 | H39: 291 | I39: 28242 | J39: =F39+G39+H39+L39 -> 3639 | K39: 27550 | L39: 87 | M39: TeslaCoInnovation | P39: SustainabilityDrive | Q39: =IFERROR( INDEX(Campaign!$C$2:$C$100, MATCH(M39, Campaign!$E$2:$E$100, 0)), 0 ) -> 0 | R39: =IFERROR( INDEX(Campaign!$C$2:$C$100, MATCH(N39, Campaign!$E$2:$E$100, 0)), 0 ) -> 0 | S39: =IFERROR( INDEX(Campaign!$C$2:$C$100, MATCH(O39, Campaign!$E$2:$E$100, 0)), 0 ) -> 0 | T39: =IF((Q39+R39+S39)=0, "", J39/(Q39+R39+S39)) | U39: =(F39+H39+G39)/I39 -> 0.12577013 | V39: =IFERROR( INDEX(Campaign!$A$2:$A$100, MATCH(M43, Campaign!$E$2:$E$100, 0)), "" ) -> 45488 | W39: =IF(TRIM(O39)="","Before", "During") -> Before
A40: P039 | B40: Facebook | C40: 45621 | D40: Image | E40: Check out our latest image on facebook! | F40: 3564 | G40: 629 | H40: 177 | I40: 60588 | J40: =F40+G40+H40+L40 -> 4462 | K40: 59627 | L40: 92 | M40: TeslaCoInnovation | Q40: =IFERROR( INDEX(Campaign!$C$2:$C$100, MATCH(M40, Campaign!$E$2:$E$100, 0)), 0 ) -> 0 | R40: =IFERROR( INDEX(Campaign!$C$2:$C$100, MATCH(N40, Campaign!$E$2:$E$100, 0)), 0 ) -> 0 | S40: =IFERROR( INDEX(Campaign!$C$2:$C$100, MATCH(O40, Campaign!$E$2:$E$100, 0)), 0 ) -> 0 | T40: =IF((Q40+R40+S40)=0, "", J40/(Q40+R40+S40)) | U40: =(F40+H40+G40)/I40 -> 0.072126494 | V40: =IFERROR( INDEX(Campaign!$A$2:$A$100, MATCH(M44, Campaign!$E$2:$E$100, 0)), "" ) | W40: =IF(TRIM(O40)="","Before", "During") -> Before
...

Sheet Engagement
A1: Week_Start_Date | B1: Platform | C1: New_Followers | D1: Unfollows | E1: Total_Followers | F1: Engagement_Rate | G1: Ad_Spend
A2: 45446 | B2: Instagram | C2: 1135 | D2: 88 | E2: 344084 | F2: 8.06 | G2: 5904
A3: 45446 | B3: Facebook | C3: 1312 | D3: 310 | E3: 42654 | F3: 4.98 | G3: 9566
A4: 45446 | B4: Twitter | C4: 584 | D4: 169 | E4: 146834 | F4: 8.31 | G4: 26752
A5: 45446 | B5: YouTube | C5: 1535 | D5: 445 | E5: 395536 | F5: 4.11 | G5: 30671
A6: 45453 | B6: Instagram | C6: 656 | D6: 139 | E6: 49157 | F6: 9.05 | G6: 9920
A7: 45453 | B7: Facebook | C7: 1697 | D7: 414 | E7: 316555 | F7: 2.37 | G7: 7924
A8: 45453 | B8: Twitter | C8: 436 | D8: 250 | E8: 254347 | F8: 4.01 | G8: 8912
A9: 45453 | B9: YouTube | C9: 1197 | D9: 203 | E9: 413878 | F9: 3.16 | G9: 21205
A10: 45460 | B10: Instagram | C10: 1048 | D10: 155 | E10: 456946 | F10: 2.46 | G10: 11329
A11: 45460 | B11: Facebook | C11: 1753 | D11: 371 | E11: 169496 | F11: 8.11 | G11: 46670
A12: 45460 | B12: Twitter | C12: 1335 | D12: 40 | E12: 122732 | F12: 8.19 | G12: 22482
A13: 45460 | B13: YouTube | C13: 403 | D13: 66 | E13: 382851 | F13: 3.49 | G13: 24313
... A201: 45789 | B201: YouTube | C201: 119 | D201: 456 | E201: 82558 | F201: 6.81 | G201: 12174

Sheet Campaign
A1: End_Date | B1: Objective | C1: Total_Budget | D1: Target_Platforms | E1: Primary_Hashtags | F1: Primary Hashtags
A2: 45488 | B2: Product Awareness | C2: 150000 | D2: Instagram,Facebook | E2: EVRevolution | F2: TeslaCoInnovation
A3: 45596 | B3: Customer Engagement | C3: 200000 | D3: Instagram,YouTube | E3: AnytimeIsTeslaTime
A4: 45667 | B4: Vehicle Launch | C4: 250000 | D4: Facebook,Twitter | E4: SmoothLikeNitroTesla
A5: 45747 | B5: Community Growth | C5: 180000 | D5: Instagram,Twitter | E5: BetterWithTesla | F5: FutureOfDriving

Sheet ROI
A3: Row Labels | B3: Average of ROI
A4: CybertruckLaunch | B4: 0.023996233
A5: FSDUpdate | B5: 0.021297118
A6: ModelYCampaign | B6: 0.02145561
A7: SustainabilityDrive | B7: 0.023611785
A8: (blank) | B8: 0.019235729
A9: Grand Total | B9: 0.022117681
A12: CybertruckLaunch had the highest ROI (engagement vs. spend)

Sheet Growth
A3: Row Labels | B3: Average of Growth
A4: CybertruckLaunch | B4: 0.12925934
A5: FSDUpdate | B5: 0.14399919
A6: ModelYCampaign | B6: 0.14125279
A7: SustainabilityDrive | B7: 0.15203856
A8: (blank) | B8: 0.17223258
A9: Grand Total | B9: 0.14828272
A13: the campaign with the strongest follower growth is SustainabilityDrive with an average growth of 0.152.

Sheet Per Compaign Engagement
A3: Row Labels | B3: Sum of Impressions | C3: Average of Impressions | D3: Sum of Likes | E3: Average of Likes | F3: Sum of Clicks | G3: Average of Clicks
A4: CybertruckLaunch | B4: 1846272 | C4: 38464 | D4: 138793 | E4: 2891.5208 | F4: 6434 | G4: 134.04167
A5: FSDUpdate | B5: 2266053 | C5: 33821.687 | D5: 183346 | E5: 2736.5075 | F5: 10032 | G5: 149.73134
A6: ModelYCampaign | B6: 1986356 | C6: 34247.517 | D6: 159783 | E6: 2754.8793 | F6: 9872 | G6: 170.2069
A7: SustainabilityDrive | B7: 2464864 | C7: 34716.394 | D7: 187909 | E7: 2646.6056 | F7: 10689 | G7: 150.5493
A8: (blank) | B8: 1830608 | C8: 32689.429 | D8: 150160 | E8: 2681.4286 | F8: 8339 | G8: 148.91071
A9: Grand Total | B9: 10394153 | C9: 34647.177 | D9: 819991 | E9: 2733.3033 | F9: 45366 | G9: 151.22
